Workbook

Sheet Summary
A1: Fedora — 3-year global-launch outcomes
A2: 10 cities at launch, first hunt free, wave-2 monetisation at month 9. All values recalculate from the Assumptions sheet.
B4: Low | C4: Medium | D4: High
A5: Year 1 revenue (£) | B5: =SUMIF(Low!$B$2:$AK$2,1,Low!$B$26:$AK$26) -> 7305.2686 | C5: =SUMIF(Medium!$B$2:$AK$2,1,Medium!$B$26:$AK$26) -> 180877.7 | D5: =SUMIF(High!$B$2:$AK$2,1,High!$B$26:$AK$26) -> 1969969.2
A6: Year 2 revenue (£) | B6: =SUMIF(Low!$B$2:$AK$2,2,Low!$B$26:$AK$26) -> 48115.167 | C6: =SUMIF(Medium!$B$2:$AK$2,2,Medium!$B$26:$AK$26) -> 430259.29 | D6: =SUMIF(High!$B$2:$AK$2,2,High!$B$26:$AK$26) -> 3533340.7
A7: Year 3 revenue (£) | B7: =SUMIF(Low!$B$2:$AK$2,3,Low!$B$26:$AK$26) -> 84540.744 | C7: =SUMIF(Medium!$B$2:$AK$2,3,Medium!$B$26:$AK$26) -> 603545.36 | D7: =SUMIF(High!$B$2:$AK$2,3,High!$B$26:$AK$26) -> 3534968.2
A8: Year 1 costs (£) | B8: =SUMIF(Low!$B$2:$AK$2,1,Low!$B$33:$AK$33) -> 631392.71 | C8: =SUMIF(Medium!$B$2:$AK$2,1,Medium!$B$33:$AK$33) -> 1284385.4 | D8: =SUMIF(High!$B$2:$AK$2,1,High!$B$33:$AK$33) -> 2236335.4
A9: Year 2 costs (£) | B9: =SUMIF(Low!$B$2:$AK$2,2,Low!$B$33:$AK$33) -> 235992.38 | C9: =SUMIF(Medium!$B$2:$AK$2,2,Medium!$B$33:$AK$33) -> 808738.33 | D9: =SUMIF(High!$B$2:$AK$2,2,High!$B$33:$AK$33) -> 1859728.1
A10: Year 3 costs (£) | B10: =SUMIF(Low!$B$2:$AK$2,3,Low!$B$33:$AK$33) -> 243717.81 | C10: =SUMIF(Medium!$B$2:$AK$2,3,Medium!$B$33:$AK$33) -> 913428.33 | D10: =SUMIF(High!$B$2:$AK$2,3,High!$B$33:$AK$33) -> 2594845.8
A11: Year 1 net (£) | B11: =SUMIF(Low!$B$2:$AK$2,1,Low!$B$34:$AK$34) -> -624087.44 | C11: =SUMIF(Medium!$B$2:$AK$2,1,Medium!$B$34:$AK$34) -> -1103507.7 | D11: =SUMIF(High!$B$2:$AK$2,1,High!$B$34:$AK$34) -> -266366.22
A12: Year 2 net (£) | B12: =SUMIF(Low!$B$2:$AK$2,2,Low!$B$34:$AK$34) -> -187877.21 | C12: =SUMIF(Medium!$B$2:$AK$2,2,Medium!$B$34:$AK$34) -> -378479.04 | D12: =SUMIF(High!$B$2:$AK$2,2,High!$B$34:$AK$34) -> 1673612.6
A13: Year 3 net (£) | B13: =SUMIF(Low!$B$2:$AK$2,3,Low!$B$34:$AK$34) -> -159177.07 | C13: =SUMIF(Medium!$B$2:$AK$2,3,Medium!$B$34:$AK$34) -> -309882.98 | D13: =SUMIF(High!$B$2:$AK$2,3,High!$B$34:$AK$34) -> 940122.41
A14: Cumulative net, 36 months (£) | B14: =Low!$AK$35 -> -971141.72 | C14: =Medium!$AK$35 -> -1791869.7 | D14: =High!$AK$35 -> 2347368.8
A15: Cash trough (£) | B15: =MIN(Low!$B$35:$AK$35) -> -971141.72 | C15: =MIN(Medium!$B$35:$AK$35) -> -1791869.7 | D15: =MIN(High!$B$35:$AK$35) -> -1790840.6
A16: Players reached (app) | B16: =SUM(Low!$B$8:$AK$8) -> 24815.405 | C16: =SUM(Medium!$B$8:$AK$8) -> 212715 | D16: =SUM(High!$B$8:$AK$8) -> 1525462.5
A18: Competitor entry month | B18: =Assumptions!$B$64 -> 30 | C18: =Assumptions!$C$64 -> 21 | D18: =Assumptions!$D$64 -> 15
A19: Revenue banked at entry (£) | B19: =INDEX(Low!$B$36:$AK$36,MATCH(Assumptions!$B$64,Low!$B$1:$AK$1,0)-1) -> 98524.495 | C19: =INDEX(Medium!$B$36:$AK$36,MATCH(Assumptions!$C$64,Medium!$B$1:$AK$1,0)-1) -> 510613.24 | D19: =INDEX(High!$B$36:$AK$36,MATCH(Assumptions!$D$64,High!$B$1:$AK$1,0)-1) -> 3004064.4
A20: Cash position at entry (£) | B20: =INDEX(Low!$B$35:$AK$35,MATCH(Assumptions!$B$64,Low!$B$1:$AK$1,0)-1) -> -890287.31 | C20: =INDEX(Medium!$B$35:$AK$35,MATCH(Assumptions!$C$64,Medium!$B$1:$AK$1,0)-1) -> -1378597.2 | D20: =INDEX(High!$B$35:$AK$35,MATCH(Assumptions!$D$64,High!$B$1:$AK$1,0)-1) -> 306038.4
A21: Players reached at entry | B21: =INDEX(Low!$B$20:$AK$20,MATCH(Assumptions!$B$64,Low!$B$1:$AK$1,0)-1) -> 23835.946 | C21: =INDEX(Medium!$B$20:$AK$20,MATCH(Assumptions!$C$64,Medium!$B$1:$AK$1,0)-1) -> 178650 | D21: =INDEX(High!$B$20:$AK$20,MATCH(Assumptions!$D$64,High!$B$1:$AK$1,0)-1) -> 1182637.5
A23: Year 3 Direct consumer (£) | B23: =SUMIF(Low!$B$2:$AK$2,3,Low!$B$17:$AK$17) -> 3311.2251 | C23: =SUMIF(Medium!$B$2:$AK$2,3,Medium!$B$17:$AK$17) -> 89650.637 | D23: =SUMIF(High!$B$2:$AK$2,3,High!$B$17:$AK$17) -> 1781306.2
A24: Year 3 OTA (£) | B24: =SUMIF(Low!$B$2:$AK$2,3,Low!$B$19:$AK$19) -> 13014 | C24: =SUMIF(Medium!$B$2:$AK$2,3,Medium!$B$19:$AK$19) -> 58320 | D24: =SUMIF(High!$B$2:$AK$2,3,High!$B$19:$AK$19) -> 172125
A25: Year 3 Advertising (£) | B25: =SUMIF(Low!$B$2:$AK$2,3,Low!$B$22:$AK$22) -> 215.51847 | C25: =SUMIF(Medium!$B$2:$AK$2,3,Medium!$B$22:$AK$22) -> 5574.72 | D25: =SUMIF(High!$B$2:$AK$2,3,High!$B$22:$AK$22) -> 125537.04
A26: Year 3 Sponsorship (£) | B26: =SUMIF(Low!$B$2:$AK$2,3,Low!$B$23:$AK$23) -> 24000 | C26: =SUMIF(Medium!$B$2:$AK$2,3,Medium!$B$23:$AK$23) -> 120000 | D26: =SUMIF(High!$B$2:$AK$2,3,High!$B$23:$AK$23) -> 400000
A27: Year 3 White-label (£) | B27: =SUMIF(Low!$B$2:$AK$2,3,Low!$B$24:$AK$24) -> 8000 | C27: =SUMIF(Medium!$B$2:$AK$2,3,Medium!$B$24:$AK$24) -> 90000 | D27: =SUMIF(High!$B$2:$AK$2,3,High!$B$24:$AK$24) -> 480000
A28: Year 3 Corporate (£) | B28: =SUMIF(Low!$B$2:$AK$2,3,Low!$B$25:$AK$25) -> 36000 | C28: =SUMIF(Medium!$B$2:$AK$2,3,Medium!$B$25:$AK$25) -> 240000 | D28: =SUMIF(High!$B$2:$AK$2,3,High!$B$25:$AK$25) -> 576000

Sheet Assumptions
A1: Fedora — global launch model: assumptions
A2: All money GBP. Blue = input cells (edit these); yellow = key levers. Sources: docs/business/research/*.md
A4: STRUCTURE & SHARED
A5: Cities at launch | B5: 10 | E5: Launch brief: one hunt per big city in 10 cities
A6: Avg players per team (one purchase covers a team) | B6: 3.5 | E6: Teams of 3-4; marketing-cac.md §5
A7: Wave-2 month (paid catalogue + sponsors + ads) | B7: 9 | E7: Launch brief: monetisation at second launch
A8: Lapsed players active per month (MAU factor) | B8: 0.08 | E8: Episodic use; D30 retention 3-5%, marketing-cac.md §2
A9: OTA players new to app (share) | B9: 0.5 | E9: OTA buyers partly overlap app installs
A10: Home-city share of catalogue | B10: 0.15 | E10: 1 of 10 launch cities is home; grows slightly
A11: Wave-2+ build discount vs first remote hunt | B11: 0.9 | E11: Repeat visits amortise city research
A12: Hunt build — home city (£) | B12: 8000 | E12: Contracted design+field+red-team+QA; competitive-response.md §3
A13: Hunt build — remote city (£) | B13: 14000 | E13: +travel/local contractor (Blue Badge £353/day; trip ~$1,771)
A14: Maintenance/yr — home hunt (£) | B14: 1200 | E14: Quarterly re-verification; world drifts
A15: Maintenance/yr — remote hunt (£) | B15: 2500 | E15: Local contractor passes; Field Agent-style spot checks
A16: AI red-team compute per hunt (£) | B16: 500 | E16: Frontier-model attack runs pre-ship (methodology step 2)
... A23: Repeat-buyer pool monthly churn | B23: 0.05 | E23: Lapse rate of paying teams
A25: SCENARIO | B25: Low | C25: Medium | D25: High | E25: Source / basis
A26: Blended CPI (£/install) | B26: 3.7 | C26: 2.4 | D26: 1.2 | E26: Tier-1 cities $1.50-6.00; marketing-cac.md §1
A27: Organic multiplier Y1 | B27: 1.25 | C27: 1.8 | D27: 2.5 | E27: PR/creators/referral uplift; decays (Randonautica)
A28: Organic multiplier Y2 | B28: 1.2 | C28: 1.6 | D28: 1.8
A29: Organic multiplier Y3 | B29: 1.2 | C29: 1.5 | D29: 1.5
A30: Install → starts free hunt | B30: 0.22 | C30: 0.3 | D30: 0.38 | E30: D1-retention-like; marketing-cac.md §2
A31: Backlog engaged-team conversion | B31: 0.03 | C31: 0.06 | D31: 0.1 | E31: Pre-wave-2 base converting when catalogue lands
A32: Engaged team → paid conversion | B32: 0.05 | C32: 0.1 | D32: 0.18 | E32: Freemium 2.1% of installs ≈ 7-10% of activated; team-level
A33: Repeat purchases/payer/yr | B33: 0.5 | C33: 1 | D33: 1.5 | E33: Capped by catalogue releases per city
A34: Price per team (£, gross) | B34: 40 | C34: 45 | D34: 50 | E34: ≈£11-14/head; Questo €8-20pp, CityDays £15-25pp
A35: OTA teams/city/month Y1 | B35: 0 | C35: 0 | D35: 0 | E35: GYG/Viator listings from wave 2
A36: OTA teams/city/month Y2 | B36: 2 | C36: 10 | D36: 25
A37: OTA teams/city/month Y3 | B37: 4 | C37: 20 | D37: 60
A38: Launch burst, months 0-2 (£) | B38: 160000 | C38: 400000 | D38: 900000 | E38: 10-city campaign £250k/£650k/£1.5M yr1; marketing-cac.md §3
A39: Marketing/month Y1 after burst (£) | B39: 7000 | C39: 27000 | D39: 55000
A40: Marketing/month Y2 (£) | B40: 5000 | C40: 18000 | D40: 45000
A41: Marketing/month Y3 (£) | B41: 5000 | C41: 15000 | D41: 40000
A42: Sponsorship per live city/yr (£) | B42: 3000 | C42: 12000 | D42: 40000 | E42: £2.5-4k / £8-15k / £30-60k; sponsorship-economics.md
A43: Cities with sponsors Y1 | B43: 2 | C43: 5 | D43: 8
A44: Cities with sponsors Y2 | B44: 5 | C44: 8 | D44: 10
A45: Cities with sponsors Y3 | B45: 8 | C45: 10 | D45: 10
A46: White-label deals Y1 | B46: 0 | C46: 1 | D46: 2 | E46: Councils/BIDs/museums; Ipswich £22.8k anchor
A47: White-label deals Y2 | B47: 1 | C47: 3 | D47: 6
A48: White-label deals Y3 | B48: 2 | C48: 6 | D48: 12
...

Sheet Low
A1: Month | B1: 0 | C1: 1 | D1: 2 | E1: 3 | F1: 4 | G1: 5 | H1: 6 | I1: 7 | J1: 8 | K1: 9 | L1: 10 | M1: 11 | N1: 12 | O1: 13 | P1: 14 | Q1: 15 | R1: 16 | S1: 17 | T1: 18 | U1: 19 | V1: 20 | W1: 21 | X1: 22 | Y1: 23 | Z1: 24 | AA1: 25 | AB1: 26 | AC1: 27 | AD1: 28 | AE1: 29 | AF1: 30 | AG1: 31 | AH1: 32 | AI1: 33 | AJ1: 34 | AK1: 35
A2: Year | B2: =1+INT(B1/12) -> 1 | C2: =1+INT(C1/12) -> 1 | D2: =1+INT(D1/12) -> 1 | E2: =1+INT(E1/12) -> 1 | F2: =1+INT(F1/12) -> 1 | G2: =1+INT(G1/12) -> 1 | H2: =1+INT(H1/12) -> 1 | I2: =1+INT(I1/12) -> 1 | ... AK2: =1+INT(AK1/12) -> 3
A3: Post-entry flag | B3: =IF(B1>=Assumptions!$B$64,1,0) -> 0 | C3: =IF(C1>=Assumptions!$B$64,1,0) -> 0 | D3: =IF(D1>=Assumptions!$B$64,1,0) -> 0 | E3: =IF(E1>=Assumptions!$B$64,1,0) -> 0 | F3: =IF(F1>=Assumptions!$B$64,1,0) -> 0 | G3: =IF(G1>=Assumptions!$B$64,1,0) -> 0 | H3: =IF(H1>=Assumptions!$B$64,1,0) -> 0 | I3: =IF(I1>=Assumptions!$B$64,1,0) -> 0 | ... AK3: =IF(AK1>=Assumptions!$B$64,1,0) -> 1
A4: Growth dampener | B4: =IF(B3=1,Assumptions!$B$65,1) -> 1 | C4: =IF(C3=1,Assumptions!$B$65,1) -> 1 | D4: =IF(D3=1,Assumptions!$B$65,1) -> 1 | E4: =IF(E3=1,Assumptions!$B$65,1) -> 1 | F4: =IF(F3=1,Assumptions!$B$65,1) -> 1 | G4: =IF(G3=1,Assumptions!$B$65,1) -> 1 | H4: =IF(H3=1,Assumptions!$B$65,1) -> 1 | I4: =IF(I3=1,Assumptions!$B$65,1) -> 1 | ... AK4: =IF(AK3=1,Assumptions!$B$65,1) -> 0.85
A5: Price per team (£) | B5: =Assumptions!$B$34*IF(B3=1,Assumptions!$B$66,1) -> 40 | C5: =Assumptions!$B$34*IF(C3=1,Assumptions!$B$66,1) -> 40 | D5: =Assumptions!$B$34*IF(D3=1,Assumptions!$B$66,1) -> 40 | E5: =Assumptions!$B$34*IF(E3=1,Assumptions!$B$66,1) -> 40 | F5: =Assumptions!$B$34*IF(F3=1,Assumptions!$B$66,1) -> 40 | G5: =Assumptions!$B$34*IF(G3=1,Assumptions!$B$66,1) -> 40 | H5: =Assumptions!$B$34*IF(H3=1,Assumptions!$B$66,1) -> 40 | I5: =Assumptions!$B$34*IF(I3=1,Assumptions!$B$66,1) -> 40 | ... AK5: =Assumptions!$B$34*IF(AK3=1,Assumptions!$B$66,1) -> 38
A6: Marketing spend (£) | B6: =IF(B1<3,Assumptions!$B$38/3,CHOOSE(B2,Assumptions!$B$39,Assumptions!$B$40,Assumptions!$B$41)) -> 53333.333 | C6: =IF(C1<3,Assumptions!$B$38/3,CHOOSE(C2,Assumptions!$B$39,Assumptions!$B$40,Assumptions!$B$41)) -> 53333.333 | D6: =IF(D1<3,Assumptions!$B$38/3,CHOOSE(D2,Assumptions!$B$39,Assumptions!$B$40,Assumptions!$B$41)) -> 53333.333 | E6: =IF(E1<3,Assumptions!$B$38/3,CHOOSE(E2,Assumptions!$B$39,Assumptions!$B$40,Assumptions!$B$41)) -> 7000 | F6: =IF(F1<3,Assumptions!$B$38/3,CHOOSE(F2,Assumptions!$B$39,Assumptions!$B$40,Assumptions!$B$41)) -> 7000 | G6: =IF(G1<3,Assumptions!$B$38/3,CHOOSE(G2,Assumptions!$B$39,Assumptions!$B$40,Assumptions!$B$41)) -> 7000 | H6: =IF(H1<3,Assumptions!$B$38/3,CHOOSE(H2,Assumptions!$B$39,Assumptions!$B$40,Assumptions!$B$41)) -> 7000 | I6: =IF(I1<3,Assumptions!$B$38/3,CHOOSE(I2,Assumptions!$B$39,Assumptions!$B$40,Assumptions!$B$41)) -> 7000 | ... AK6: =IF(AK1<3,Assumptions!$B$38/3,CHOOSE(AK2,Assumptions!$B$39,Assumptions!$B$40,Assumptions!$B$41)) -> 5000
A7: Installs | B7: =B6/Assumptions!$B$26*CHOOSE(B2,Assumptions!$B$27,Assumptions!$B$28,Assumptions!$B$29)*B4 -> 18018.018 | C7: =C6/Assumptions!$B$26*CHOOSE(C2,Assumptions!$B$27,Assumptions!$B$28,Assumptions!$B$29)*C4 -> 18018.018 | D7: =D6/Assumptions!$B$26*CHOOSE(D2,Assumptions!$B$27,Assumptions!$B$28,Assumptions!$B$29)*D4 -> 18018.018 | E7: =E6/Assumptions!$B$26*CHOOSE(E2,Assumptions!$B$27,Assumptions!$B$28,Assumptions!$B$29)*E4 -> 2364.8649 | F7: =F6/Assumptions!$B$26*CHOOSE(F2,Assumptions!$B$27,Assumptions!$B$28,Assumptions!$B$29)*F4 -> 2364.8649 | G7: =G6/Assumptions!$B$26*CHOOSE(G2,Assumptions!$B$27,Assumptions!$B$28,Assumptions!$B$29)*G4 -> 2364.8649 | H7: =H6/Assumptions!$B$26*CHOOSE(H2,Assumptions!$B$27,Assumptions!$B$28,Assumptions!$B$29)*H4 -> 2364.8649 | I7: =I6/Assumptions!$B$26*CHOOSE(I2,Assumptions!$B$27,Assumptions!$B$28,Assumptions!$B$29)*I4 -> 2364.8649 | ... AK7: =AK6/Assumptions!$B$26*CHOOSE(AK2,Assumptions!$B$27,Assumptions!$B$28,Assumptions!$B$29)*AK4 -> 1378.3784
A8: New active players | B8: =B7*Assumptions!$B$30 -> 3963.964 | C8: =C7*Assumptions!$B$30 -> 3963.964 | D8: =D7*Assumptions!$B$30 -> 3963.964 | E8: =E7*Assumptions!$B$30 -> 520.27027 | F8: =F7*Assumptions!$B$30 -> 520.27027 | G8: =G7*Assumptions!$B$30 -> 520.27027 | H8: =H7*Assumptions!$B$30 -> 520.27027 | I8: =I7*Assumptions!$B$30 -> 520.27027 | ... AK8: =AK7*Assumptions!$B$30 -> 303.24324
A9: New active teams | B9: =B8/Assumptions!$B$6 -> 1132.5611 | C9: =C8/Assumptions!$B$6 -> 1132.5611 | D9: =D8/Assumptions!$B$6 -> 1132.5611 | E9: =E8/Assumptions!$B$6 -> 148.64865 | F9: =F8/Assumptions!$B$6 -> 148.64865 | G9: =G8/Assumptions!$B$6 -> 148.64865 | H9: =H8/Assumptions!$B$6 -> 148.64865 | I9: =I8/Assumptions!$B$6 -> 148.64865 | ... AK9: =AK8/Assumptions!$B$6 -> 86.640927
A10: Backlog pool (teams) | B10: =B9 -> 1132.5611 | C10: =IF(C1<Assumptions!$B$7,B10+C9,IF(C1<=Assumptions!$B$7+1,B10*2/3,0)) -> 2265.1223 | D10: =IF(D1<Assumptions!$B$7,C10+D9,IF(D1<=Assumptions!$B$7+1,C10*2/3,0)) -> 3397.6834 | E10: =IF(E1<Assumptions!$B$7,D10+E9,IF(E1<=Assumptions!$B$7+1,D10*2/3,0)) -> 3546.332 | F10: =IF(F1<Assumptions!$B$7,E10+F9,IF(F1<=Assumptions!$B$7+1,E10*2/3,0)) -> 3694.9807 | G10: =IF(G1<Assumptions!$B$7,F10+G9,IF(G1<=Assumptions!$B$7+1,F10*2/3,0)) -> 3843.6293 | H10: =IF(H1<Assumptions!$B$7,G10+H9,IF(H1<=Assumptions!$B$7+1,G10*2/3,0)) -> 3992.278 | I10: =IF(I1<Assumptions!$B$7,H10+I9,IF(I1<=Assumptions!$B$7+1,H10*2/3,0)) -> 4140.9266 | J10: =IF(J1<Assumptions!$B$7,I10+J9,IF(J1<=Assumptions!$B$7+1,I10*2/3,0)) -> 4289.5753 | ... AK10: =IF(AK1<Assumptions!$B$7,AJ10+AK9,IF(AK1<=Assumptions!$B$7+1,AJ10*2/3,0)) -> 0
A11: Backlog tranche | B11: =0 -> 0 | C11: =IF(C1<Assumptions!$B$7,0,IF(C1<=Assumptions!$B$7+1,B10/3,IF(C1=Assumptions!$B$7+2,B10,0))) -> 0 | D11: =IF(D1<Assumptions!$B$7,0,IF(D1<=Assumptions!$B$7+1,C10/3,IF(D1=Assumptions!$B$7+2,C10,0))) -> 0 | E11: =IF(E1<Assumptions!$B$7,0,IF(E1<=Assumptions!$B$7+1,D10/3,IF(E1=Assumptions!$B$7+2,D10,0))) -> 0 | F11: =IF(F1<Assumptions!$B$7,0,IF(F1<=Assumptions!$B$7+1,E10/3,IF(F1=Assumptions!$B$7+2,E10,0))) -> 0 | G11: =IF(G1<Assumptions!$B$7,0,IF(G1<=Assumptions!$B$7+1,F10/3,IF(G1=Assumptions!$B$7+2,F10,0))) -> 0 | H11: =IF(H1<Assumptions!$B$7,0,IF(H1<=Assumptions!$B$7+1,G10/3,IF(H1=Assumptions!$B$7+2,G10,0))) -> 0 | I11: =IF(I1<Assumptions!$B$7,0,IF(I1<=Assumptions!$B$7+1,H10/3,IF(I1=Assumptions!$B$7+2,H10,0))) -> 0 | J11: =IF(J1<Assumptions!$B$7,0,IF(J1<=Assumptions!$B$7+1,I10/3,IF(J1=Assumptions!$B$7+2,I10,0))) -> 0 | ... AK11: =IF(AK1<Assumptions!$B$7,0,IF(AK1<=Assumptions!$B$7+1,AJ10/3,IF(AK1=Assumptions!$B$7+2,AJ10,0))) -> 0
A12: New paying teams | B12: =B11*Assumptions!$B$31+IF(B1>=Assumptions!$B$7,B9*Assumptions!$B$32,0) -> 0 | C12: =C11*Assumptions!$B$31+IF(C1>=Assumptions!$B$7,C9*Assumptions!$B$32,0) -> 0 | D12: =D11*Assumptions!$B$31+IF(D1>=Assumptions!$B$7,D9*Assumptions!$B$32,0) -> 0 | E12: =E11*Assumptions!$B$31+IF(E1>=Assumptions!$B$7,E9*Assumptions!$B$32,0) -> 0 | F12: =F11*Assumptions!$B$31+IF(F1>=Assumptions!$B$7,F9*Assumptions!$B$32,0) -> 0 | G12: =G11*Assumptions!$B$31+IF(G1>=Assumptions!$B$7,G9*Assumptions!$B$32,0) -> 0 | H12: =H11*Assumptions!$B$31+IF(H1>=Assumptions!$B$7,H9*Assumptions!$B$32,0) -> 0 | I12: =I11*Assumptions!$B$31+IF(I1>=Assumptions!$B$7,I9*Assumptions!$B$32,0) -> 0 | ... AK12: =AK11*Assumptions!$B$31+IF(AK1>=Assumptions!$B$7,AK9*Assumptions!$B$32,0) -> 4.3320463
A13: Repeat rate (monthly) | B13: =MIN(Assumptions!$B$33,CHOOSE(B2,Assumptions!$B$58,Assumptions!$B$59,Assumptions!$B$60)/Assumptions!$B$5)/12 -> 0.041666667 | C13: =MIN(Assumptions!$B$33,CHOOSE(C2,Assumptions!$B$58,Assumptions!$B$59,Assumptions!$B$60)/Assumptions!$B$5)/12 -> 0.041666667 | D13: =MIN(Assumptions!$B$33,CHOOSE(D2,Assumptions!$B$58,Assumptions!$B$59,Assumptions!$B$60)/Assumptions!$B$5)/12 -> 0.041666667 | E13: =MIN(Assumptions!$B$33,CHOOSE(E2,Assumptions!$B$58,Assumptions!$B$59,Assumptions!$B$60)/Assumptions!$B$5)/12 -> 0.041666667 | F13: =MIN(Assumptions!$B$33,CHOOSE(F2,Assumptions!$B$58,Assumptions!$B$59,Assumptions!$B$60)/Assumptions!$B$5)/12 -> 0.041666667 | G13: =MIN(Assumptions!$B$33,CHOOSE(G2,Assumptions!$B$58,Assumptions!$B$59,Assumptions!$B$60)/Assumptions!$B$5)/12 -> 0.041666667 | H13: =MIN(Assumptions!$B$33,CHOOSE(H2,Assumptions!$B$58,Assumptions!$B$59,Assumptions!$B$60)/Assumptions!$B$5)/12 -> 0.041666667 | I13: =MIN(Assumptions!$B$33,CHOOSE(I2,Assumptions!$B$58,Assumptions!$B$59,Assumptions!$B$60)/Assumptions!$B$5)/12 -> 0.041666667 | ... AK13: =MIN(Assumptions!$B$33,CHOOSE(AK2,Assumptions!$B$58,Assumptions!$B$59,Assumptions!$B$60)/Assumptions!$B$5)/12 -> 0.025
A14: Repeat purchases | B14: =0 -> 0 | C14: =B15*C13 -> 0 | D14: =C15*D13 -> 0 | E14: =D15*E13 -> 0 | F14: =E15*F13 -> 0 | G14: =F15*G13 -> 0 | H14: =G15*H13 -> 0 | I14: =H15*I13 -> 0 | J14: =I15*J13 -> 0 | ... AK14: =AJ15*AK13 -> 2.7871728
A15: Paying-team base | B15: =B12 -> 0 | C15: =B15*(1-Assumptions!$B$23)+C12 -> 0 | D15: =C15*(1-Assumptions!$B$23)+D12 -> 0 | E15: =D15*(1-Assumptions!$B$23)+E12 -> 0 | F15: =E15*(1-Assumptions!$B$23)+F12 -> 0 | G15: =F15*(1-Assumptions!$B$23)+G12 -> 0 | H15: =G15*(1-Assumptions!$B$23)+H12 -> 0 | I15: =H15*(1-Assumptions!$B$23)+I12 -> 0 | J15: =I15*(1-Assumptions!$B$23)+J12 -> 0 | ... AK15: =AJ15*(1-Assumptions!$B$23)+AK12 -> 110.24461
A16: Paid team purchases | B16: =B12+B14 -> 0 | C16: =C12+C14 -> 0 | D16: =D12+D14 -> 0 | E16: =E12+E14 -> 0 | F16: =F12+F14 -> 0 | G16: =G12+G14 -> 0 | H16: =H12+H14 -> 0 | I16: =I12+I14 -> 0 | ... AK16: =AK12+AK14 -> 7.1192191
A17: Direct consumer net (£) | B17: =B16*B5*(1-Assumptions!$B$19) -> 0 | C17: =C16*C5*(1-Assumptions!$B$19) -> 0 | D17: =D16*D5*(1-Assumptions!$B$19) -> 0 | E17: =E16*E5*(1-Assumptions!$B$19) -> 0 | F17: =F16*F5*(1-Assumptions!$B$19) -> 0 | G17: =G16*G5*(1-Assumptions!$B$19) -> 0 | H17: =H16*H5*(1-Assumptions!$B$19) -> 0 | I17: =I16*I5*(1-Assumptions!$B$19) -> 0 | ... AK17: =AK16*AK5*(1-Assumptions!$B$19) -> 248.8879
A18: OTA teams | B18: =IF(B1>=Assumptions!$B$7,CHOOSE(B2,Assumptions!$B$35,Assumptions!$B$36,Assumptions!$B$37)*Assumptions!$B$5*B4,0) -> 0 | C18: =IF(C1>=Assumptions!$B$7,CHOOSE(C2,Assumptions!$B$35,Assumptions!$B$36,Assumptions!$B$37)*Assumptions!$B$5*C4,0) -> 0 | D18: =IF(D1>=Assumptions!$B$7,CHOOSE(D2,Assumptions!$B$35,Assumptions!$B$36,Assumptions!$B$37)*Assumptions!$B$5*D4,0) -> 0 | E18: =IF(E1>=Assumptions!$B$7,CHOOSE(E2,Assumptions!$B$35,Assumptions!$B$36,Assumptions!$B$37)*Assumptions!$B$5*E4,0) -> 0 | F18: =IF(F1>=Assumptions!$B$7,CHOOSE(F2,Assumptions!$B$35,Assumptions!$B$36,Assumptions!$B$37)*Assumptions!$B$5*F4,0) -> 0 | G18: =IF(G1>=Assumptions!$B$7,CHOOSE(G2,Assumptions!$B$35,Assumptions!$B$36,Assumptions!$B$37)*Assumptions!$B$5*G4,0) -> 0 | H18: =IF(H1>=Assumptions!$B$7,CHOOSE(H2,Assumptions!$B$35,Assumptions!$B$36,Assumptions!$B$37)*Assumptions!$B$5*H4,0) -> 0 | I18: =IF(I1>=Assumptions!$B$7,CHOOSE(I2,Assumptions!$B$35,Assumptions!$B$36,Assumptions!$B$37)*Assumptions!$B$5*I4,0) -> 0 | ... AK18: =IF(AK1>=Assumptions!$B$7,CHOOSE(AK2,Assumptions!$B$35,Assumptions!$B$36,Assumptions!$B$37)*Assumptions!$B$5*AK4,0) -> 34
A19: OTA net (£) | B19: =B18*B5*(1-Assumptions!$B$20) -> 0 | C19: =C18*C5*(1-Assumptions!$B$20) -> 0 | D19: =D18*D5*(1-Assumptions!$B$20) -> 0 | E19: =E18*E5*(1-Assumptions!$B$20) -> 0 | F19: =F18*F5*(1-Assumptions!$B$20) -> 0 | G19: =G18*G5*(1-Assumptions!$B$20) -> 0 | H19: =H18*H5*(1-Assumptions!$B$20) -> 0 | I19: =I18*I5*(1-Assumptions!$B$20) -> 0 | ... AK19: =AK18*AK5*(1-Assumptions!$B$20) -> 969
A20: Cumulative players | B20: =B8+B18*Assumptions!$B$6*Assumptions!$B$9 -> 3963.964 | C20: =B20+C8+C18*Assumptions!$B$6*Assumptions!$B$9 -> 7927.9279 | D20: =C20+D8+D18*Assumptions!$B$6*Assumptions!$B$9 -> 11891.892 | E20: =D20+E8+E18*Assumptions!$B$6*Assumptions!$B$9 -> 12412.162 | F20: =E20+F8+F18*Assumptions!$B$6*Assumptions!$B$9 -> 12932.432 | G20: =F20+G8+G18*Assumptions!$B$6*Assumptions!$B$9 -> 13452.703 | H20: =G20+H8+H18*Assumptions!$B$6*Assumptions!$B$9 -> 13972.973 | I20: =H20+I8+I18*Assumptions!$B$6*Assumptions!$B$9 -> 14493.243 | J20: =I20+J8+J18*Assumptions!$B$6*Assumptions!$B$9 -> 15013.514 | ... AK20: =AJ20+AK8+AK18*Assumptions!$B$6*Assumptions!$B$9 -> 26012.405
A21: MAU | B21: =B8+Assumptions!$B$8*B20 -> 4281.0811 | C21: =C8+Assumptions!$B$8*C20 -> 4598.1982 | D21: =D8+Assumptions!$B$8*D20 -> 4915.3153 | E21: =E8+Assumptions!$B$8*E20 -> 1513.2432 | F21: =F8+Assumptions!$B$8*F20 -> 1554.8649 | G21: =G8+Assumptions!$B$8*G20 -> 1596.4865 | H21: =H8+Assumptions!$B$8*H20 -> 1638.1081 | I21: =I8+Assumptions!$B$8*I20 -> 1679.7297 | ... AK21: =AK8+Assumptions!$B$8*AK20 -> 2384.2357
A22: Advertising (£) | B22: =IF(B1>=Assumptions!$B$7,B21/1000*Assumptions!$B$50,0) -> 0 | C22: =IF(C1>=Assumptions!$B$7,C21/1000*Assumptions!$B$50,0) -> 0 | D22: =IF(D1>=Assumptions!$B$7,D21/1000*Assumptions!$B$50,0) -> 0 | E22: =IF(E1>=Assumptions!$B$7,E21/1000*Assumptions!$B$50,0) -> 0 | F22: =IF(F1>=Assumptions!$B$7,F21/1000*Assumptions!$B$50,0) -> 0 | G22: =IF(G1>=Assumptions!$B$7,G21/1000*Assumptions!$B$50,0) -> 0 | H22: =IF(H1>=Assumptions!$B$7,H21/1000*Assumptions!$B$50,0) -> 0 | I22: =IF(I1>=Assumptions!$B$7,I21/1000*Assumptions!$B$50,0) -> 0 | ... AK22: =IF(AK1>=Assumptions!$B$7,AK21/1000*Assumptions!$B$50,0) -> 19.073885
A23: Sponsorship (£) | B23: =IF(B1>=Assumptions!$B$7,CHOOSE(B2,Assumptions!$B$43,Assumptions!$B$44,Assumptions!$B$45)*Assumptions!$B$42/12,0) -> 0 | C23: =IF(C1>=Assumptions!$B$7,CHOOSE(C2,Assumptions!$B$43,Assumptions!$B$44,Assumptions!$B$45)*Assumptions!$B$42/12,0) -> 0 | D23: =IF(D1>=Assumptions!$B$7,CHOOSE(D2,Assumptions!$B$43,Assumptions!$B$44,Assumptions!$B$45)*Assumptions!$B$42/12,0) -> 0 | E23: =IF(E1>=Assumptions!$B$7,CHOOSE(E2,Assumptions!$B$43,Assumptions!$B$44,Assumptions!$B$45)*Assumptions!$B$42/12,0) -> 0 | F23: =IF(F1>=Assumptions!$B$7,CHOOSE(F2,Assumptions!$B$43,Assumptions!$B$44,Assumptions!$B$45)*Assumptions!$B$42/12,0) -> 0 | G23: =IF(G1>=Assumptions!$B$7,CHOOSE(G2,Assumptions!$B$43,Assumptions!$B$44,Assumptions!$B$45)*Assumptions!$B$42/12,0) -> 0 | H23: =IF(H1>=Assumptions!$B$7,CHOOSE(H2,Assumptions!$B$43,Assumptions!$B$44,Assumptions!$B$45)*Assumptions!$B$42/12,0) -> 0 | I23: =IF(I1>=Assumptions!$B$7,CHOOSE(I2,Assumptions!$B$43,Assumptions!$B$44,Assumptions!$B$45)*Assumptions!$B$42/12,0) -> 0 | ... AK23: =IF(AK1>=Assumptions!$B$7,CHOOSE(AK2,Assumptions!$B$43,Assumptions!$B$44,Assumptions!$B$45)*Assumptions!$B$42/12,0) -> 2000
A24: White-label (£) | B24: =CHOOSE(B2,Assumptions!$B$46,Assumptions!$B$47,Assumptions!$B$48)*Assumptions!$B$49/12 -> 0 | C24: =CHOOSE(C2,Assumptions!$B$46,Assumptions!$B$47,Assumptions!$B$48)*Assumptions!$B$49/12 -> 0 | D24: =CHOOSE(D2,Assumptions!$B$46,Assumptions!$B$47,Assumptions!$B$48)*Assumptions!$B$49/12 -> 0 | E24: =CHOOSE(E2,Assumptions!$B$46,Assumptions!$B$47,Assumptions!$B$48)*Assumptions!$B$49/12 -> 0 | F24: =CHOOSE(F2,Assumptions!$B$46,Assumptions!$B$47,Assumptions!$B$48)*Assumptions!$B$49/12 -> 0 | G24: =CHOOSE(G2,Assumptions!$B$46,Assumptions!$B$47,Assumptions!$B$48)*Assumptions!$B$49/12 -> 0 | H24: =CHOOSE(H2,Assumptions!$B$46,Assumptions!$B$47,Assumptions!$B$48)*Assumptions!$B$49/12 -> 0 | I24: =CHOOSE(I2,Assumptions!$B$46,Assumptions!$B$47,Assumptions!$B$48)*Assumptions!$B$49/12 -> 0 | ... AK24: =CHOOSE(AK2,Assumptions!$B$46,Assumptions!$B$47,Assumptions!$B$48)*Assumptions!$B$49/12 -> 666.66667
A25: Corporate revenue (£) | B25: =CHOOSE(B2,Assumptions!$B$51,Assumptions!$B$52,Assumptions!$B$53)*Assumptions!$B$54 -> 0 | C25: =CHOOSE(C2,Assumptions!$B$51,Assumptions!$B$52,Assumptions!$B$53)*Assumptions!$B$54 -> 0 | D25: =CHOOSE(D2,Assumptions!$B$51,Assumptions!$B$52,Assumptions!$B$53)*Assumptions!$B$54 -> 0 | E25: =CHOOSE(E2,Assumptions!$B$51,Assumptions!$B$52,Assumptions!$B$53)*Assumptions!$B$54 -> 0 | F25: =CHOOSE(F2,Assumptions!$B$51,Assumptions!$B$52,Assumptions!$B$53)*Assumptions!$B$54 -> 0 | G25: =CHOOSE(G2,Assumptions!$B$51,Assumptions!$B$52,Assumptions!$B$53)*Assumptions!$B$54 -> 0 | H25: =CHOOSE(H2,Assumptions!$B$51,Assumptions!$B$52,Assumptions!$B$53)*Assumptions!$B$54 -> 0 | I25: =CHOOSE(I2,Assumptions!$B$51,Assumptions!$B$52,Assumptions!$B$53)*Assumptions!$B$54 -> 0 | ... AK25: =CHOOSE(AK2,Assumptions!$B$51,Assumptions!$B$52,Assumptions!$B$53)*Assumptions!$B$54 -> 3000
A26: TOTAL REVENUE (£) | B26: =B17+B19+B22+B23+B24+B25 -> 0 | C26: =C17+C19+C22+C23+C24+C25 -> 0 | D26: =D17+D19+D22+D23+D24+D25 -> 0 | E26: =E17+E19+E22+E23+E24+E25 -> 0 | F26: =F17+F19+F22+F23+F24+F25 -> 0 | G26: =G17+G19+G22+G23+G24+G25 -> 0 | H26: =H17+H19+H22+H23+H24+H25 -> 0 | I26: =I17+I19+I22+I23+I24+I25 -> 0 | ... AK26: =AK17+AK19+AK22+AK23+AK24+AK25 -> 6903.6285
A27: New hunts built | B27: =CHOOSE(B2,Assumptions!$B$58,Assumptions!$B$59,Assumptions!$B$60)/12 -> 0.41666667 | C27: =CHOOSE(C2,Assumptions!$B$58,Assumptions!$B$59,Assumptions!$B$60)/12 -> 0.41666667 | D27: =CHOOSE(D2,Assumptions!$B$58,Assumptions!$B$59,Assumptions!$B$60)/12 -> 0.41666667 | E27: =CHOOSE(E2,Assumptions!$B$58,Assumptions!$B$59,Assumptions!$B$60)/12 -> 0.41666667 | F27: =CHOOSE(F2,Assumptions!$B$58,Assumptions!$B$59,Assumptions!$B$60)/12 -> 0.41666667 | G27: =CHOOSE(G2,Assumptions!$B$58,Assumptions!$B$59,Assumptions!$B$60)/12 -> 0.41666667 | H27: =CHOOSE(H2,Assumptions!$B$58,Assumptions!$B$59,Assumptions!$B$60)/12 -> 0.41666667 | I27: =CHOOSE(I2,Assumptions!$B$58,Assumptions!$B$59,Assumptions!$B$60)/12 -> 0.41666667 | ... AK27: =CHOOSE(AK2,Assumptions!$B$58,Assumptions!$B$59,Assumptions!$B$60)/12 -> 0.25
A28: Live hunts | B28: =Assumptions!$B$5+B27 -> 10.416667 | C28: =B28+C27 -> 10.833333 | D28: =C28+D27 -> 11.25 | E28: =D28+E27 -> 11.666667 | F28: =E28+F27 -> 12.083333 | G28: =F28+G27 -> 12.5 | H28: =G28+H27 -> 12.916667 | I28: =H28+I27 -> 13.333333 | J28: =I28+J27 -> 13.75 | ... AK28: =AJ28+AK27 -> 21
A29: Content build (£) | B29: =IF(B1=0,Assumptions!$B$12+Assumptions!$B$16+(Assumptions!$B$5-1)*(Assumptions!$B$13+Assumptions!$B$16),0)+B27*(Assumptions!$B$13*Assumptions!$B$11+Assumptions!$B$16) -> 144458.33 | C29: =IF(C1=0,Assumptions!$B$12+Assumptions!$B$16+(Assumptions!$B$5-1)*(Assumptions!$B$13+Assumptions!$B$16),0)+C27*(Assumptions!$B$13*Assumptions!$B$11+Assumptions!$B$16) -> 5458.3333 | D29: =IF(D1=0,Assumptions!$B$12+Assumptions!$B$16+(Assumptions!$B$5-1)*(Assumptions!$B$13+Assumptions!$B$16),0)+D27*(Assumptions!$B$13*Assumptions!$B$11+Assumptions!$B$16) -> 5458.3333 | E29: =IF(E1=0,Assumptions!$B$12+Assumptions!$B$16+(Assumptions!$B$5-1)*(Assumptions!$B$13+Assumptions!$B$16),0)+E27*(Assumptions!$B$13*Assumptions!$B$11+Assumptions!$B$16) -> 5458.3333 | F29: =IF(F1=0,Assumptions!$B$12+Assumptions!$B$16+(Assumptions!$B$5-1)*(Assumptions!$B$13+Assumptions!$B$16),0)+F27*(Assumptions!$B$13*Assumptions!$B$11+Assumptions!$B$16) -> 5458.3333 | G29: =IF(G1=0,Assumptions!$B$12+Assumptions!$B$16+(Assumptions!$B$5-1)*(Assumptions!$B$13+Assumptions!$B$16),0)+G27*(Assumptions!$B$13*Assumptions!$B$11+Assumptions!$B$16) -> 5458.3333 | H29: =IF(H1=0,Assumptions!$B$12+Assumptions!$B$16+(Assumptions!$B$5-1)*(Assumptions!$B$13+Assumptions!$B$16),0)+H27*(Assumptions!$B$13*Assumptions!$B$11+Assumptions!$B$16) -> 5458.3333 | I29: =IF(I1=0,Assumptions!$B$12+Assumptions!$B$16+(Assumptions!$B$5-1)*(Assumptions!$B$13+Assumptions!$B$16),0)+I27*(Assumptions!$B$13*Assumptions!$B$11+Assumptions!$B$16) -> 5458.3333 | ... AK29: =IF(AK1=0,Assumptions!$B$12+Assumptions!$B$16+(Assumptions!$B$5-1)*(Assumptions!$B$13+Assumptions!$B$16),0)+AK27*(Assumptions!$B$13*Assumptions!$B$11+Assumptions!$B$16) -> 3275
A30: Content maintenance (£) | B30: =B28*CHOOSE(B2,Assumptions!$B$61,Assumptions!$B$62,Assumptions!$B$63)*(Assumptions!$B$10*Assumptions!$B$14+(1-Assumptions!$B$10)*Assumptions!$B$15)/12 -> 2000.8681 | C30: =C28*CHOOSE(C2,Assumptions!$B$61,Assumptions!$B$62,Assumptions!$B$63)*(Assumptions!$B$10*Assumptions!$B$14+(1-Assumptions!$B$10)*Assumptions!$B$15)/12 -> 2080.9028 | D30: =D28*CHOOSE(D2,Assumptions!$B$61,Assumptions!$B$62,Assumptions!$B$63)*(Assumptions!$B$10*Assumptions!$B$14+(1-Assumptions!$B$10)*Assumptions!$B$15)/12 -> 2160.9375 | E30: =E28*CHOOSE(E2,Assumptions!$B$61,Assumptions!$B$62,Assumptions!$B$63)*(Assumptions!$B$10*Assumptions!$B$14+(1-Assumptions!$B$10)*Assumptions!$B$15)/12 -> 2240.9722 | F30: =F28*CHOOSE(F2,Assumptions!$B$61,Assumptions!$B$62,Assumptions!$B$63)*(Assumptions!$B$10*Assumptions!$B$14+(1-Assumptions!$B$10)*Assumptions!$B$15)/12 -> 2321.0069 | G30: =G28*CHOOSE(G2,Assumptions!$B$61,Assumptions!$B$62,Assumptions!$B$63)*(Assumptions!$B$10*Assumptions!$B$14+(1-Assumptions!$B$10)*Assumptions!$B$15)/12 -> 2401.0417 | H30: =H28*CHOOSE(H2,Assumptions!$B$61,Assumptions!$B$62,Assumptions!$B$63)*(Assumptions!$B$10*Assumptions!$B$14+(1-Assumptions!$B$10)*Assumptions!$B$15)/12 -> 2481.0764 | I30: =I28*CHOOSE(I2,Assumptions!$B$61,Assumptions!$B$62,Assumptions!$B$63)*(Assumptions!$B$10*Assumptions!$B$14+(1-Assumptions!$B$10)*Assumptions!$B$15)/12 -> 2561.1111 | ... AK30: =AK28*CHOOSE(AK2,Assumptions!$B$61,Assumptions!$B$62,Assumptions!$B$63)*(Assumptions!$B$10*Assumptions!$B$14+(1-Assumptions!$B$10)*Assumptions!$B$15)/12 -> 2016.875
A31: Staff (£) | B31: =CHOOSE(B2,Assumptions!$B$55,Assumptions!$B$56,Assumptions!$B$57) -> 10000 | C31: =CHOOSE(C2,Assumptions!$B$55,Assumptions!$B$56,Assumptions!$B$57) -> 10000 | D31: =CHOOSE(D2,Assumptions!$B$55,Assumptions!$B$56,Assumptions!$B$57) -> 10000 | E31: =CHOOSE(E2,Assumptions!$B$55,Assumptions!$B$56,Assumptions!$B$57) -> 10000 | F31: =CHOOSE(F2,Assumptions!$B$55,Assumptions!$B$56,Assumptions!$B$57) -> 10000 | G31: =CHOOSE(G2,Assumptions!$B$55,Assumptions!$B$56,Assumptions!$B$57) -> 10000 | H31: =CHOOSE(H2,Assumptions!$B$55,Assumptions!$B$56,Assumptions!$B$57) -> 10000 | I31: =CHOOSE(I2,Assumptions!$B$55,Assumptions!$B$56,Assumptions!$B$57) -> 10000 | ... AK31: =CHOOSE(AK2,Assumptions!$B$55,Assumptions!$B$56,Assumptions!$B$57) -> 8000
A32: Other costs (£) | B32: =IF(B1=0,Assumptions!$B$18,0)+Assumptions!$B$17+B25*Assumptions!$B$21+B24*Assumptions!$B$22 -> 45800 | C32: =IF(C1=0,Assumptions!$B$18,0)+Assumptions!$B$17+C25*Assumptions!$B$21+C24*Assumptions!$B$22 -> 800 | D32: =IF(D1=0,Assumptions!$B$18,0)+Assumptions!$B$17+D25*Assumptions!$B$21+D24*Assumptions!$B$22 -> 800 | E32: =IF(E1=0,Assumptions!$B$18,0)+Assumptions!$B$17+E25*Assumptions!$B$21+E24*Assumptions!$B$22 -> 800 | F32: =IF(F1=0,Assumptions!$B$18,0)+Assumptions!$B$17+F25*Assumptions!$B$21+F24*Assumptions!$B$22 -> 800 | G32: =IF(G1=0,Assumptions!$B$18,0)+Assumptions!$B$17+G25*Assumptions!$B$21+G24*Assumptions!$B$22 -> 800 | H32: =IF(H1=0,Assumptions!$B$18,0)+Assumptions!$B$17+H25*Assumptions!$B$21+H24*Assumptions!$B$22 -> 800 | I32: =IF(I1=0,Assumptions!$B$18,0)+Assumptions!$B$17+I25*Assumptions!$B$21+I24*Assumptions!$B$22 -> 800 | ... AK32: =IF(AK1=0,Assumptions!$B$18,0)+Assumptions!$B$17+AK25*Assumptions!$B$21+AK24*Assumptions!$B$22 -> 2150
A33: TOTAL COSTS (£) | B33: =B6+B29+B30+B31+B32 -> 255592.53 | C33: =C6+C29+C30+C31+C32 -> 71672.569 | D33: =D6+D29+D30+D31+D32 -> 71752.604 | E33: =E6+E29+E30+E31+E32 -> 25499.306 | F33: =F6+F29+F30+F31+F32 -> 25579.34 | G33: =G6+G29+G30+G31+G32 -> 25659.375 | H33: =H6+H29+H30+H31+H32 -> 25739.41 | I33: =I6+I29+I30+I31+I32 -> 25819.444 | ... AK33: =AK6+AK29+AK30+AK31+AK32 -> 20441.875
A34: NET (£) | B34: =B26-B33 -> -255592.53 | C34: =C26-C33 -> -71672.569 | D34: =D26-D33 -> -71752.604 | E34: =E26-E33 -> -25499.306 | F34: =F26-F33 -> -25579.34 | G34: =G26-G33 -> -25659.375 | H34: =H26-H33 -> -25739.41 | I34: =I26-I33 -> -25819.444 | ... AK34: =AK26-AK33 -> -13538.247
A35: Cumulative net (£) | B35: =B34 -> -255592.53 | C35: =B35+C34 -> -327265.1 | D35: =C35+D34 -> -399017.71 | E35: =D35+E34 -> -424517.01 | F35: =E35+F34 -> -450096.35 | G35: =F35+G34 -> -475755.73 | H35: =G35+H34 -> -501495.14 | I35: =H35+I34 -> -527314.58 | J35: =I35+J34 -> -553214.06 | ... AK35: =AJ35+AK34 -> -971141.72
A36: Cumulative revenue (£) | B36: =B26 -> 0 | C36: =B36+C26 -> 0 | D36: =C36+D26 -> 0 | E36: =D36+E26 -> 0 | F36: =E36+F26 -> 0 | G36: =F36+G26 -> 0 | H36: =G36+H26 -> 0 | I36: =H36+I26 -> 0 | J36: =I36+J26 -> 0 | ... AK36: =AJ36+AK26 -> 139961.18

Sheet Medium
A1: Month | B1: 0 | C1: 1 | D1: 2 | E1: 3 | F1: 4 | G1: 5 | H1: 6 | I1: 7 | J1: 8 | K1: 9 | L1: 10 | M1: 11 | N1: 12 | O1: 13 | P1: 14 | Q1: 15 | R1: 16 | S1: 17 | T1: 18 | U1: 19 | V1: 20 | W1: 21 | X1: 22 | Y1: 23 | Z1: 24 | AA1: 25 | AB1: 26 | AC1: 27 | AD1: 28 | AE1: 29 | AF1: 30 | AG1: 31 | AH1: 32 | AI1: 33 | AJ1: 34 | AK1: 35
A2: Year | B2: =1+INT(B1/12) -> 1 | C2: =1+INT(C1/12) -> 1 | D2: =1+INT(D1/12) -> 1 | E2: =1+INT(E1/12) -> 1 | F2: =1+INT(F1/12) -> 1 | G2: =1+INT(G1/12) -> 1 | H2: =1+INT(H1/12) -> 1 | I2: =1+INT(I1/12) -> 1 | ... AK2: =1+INT(AK1/12) -> 3
A3: Post-entry flag | B3: =IF(B1>=Assumptions!$C$64,1,0) -> 0 | C3: =IF(C1>=Assumptions!$C$64,1,0) -> 0 | D3: =IF(D1>=Assumptions!$C$64,1,0) -> 0 | E3: =IF(E1>=Assumptions!$C$64,1,0) -> 0 | F3: =IF(F1>=Assumptions!$C$64,1,0) -> 0 | G3: =IF(G1>=Assumptions!$C$64,1,0) -> 0 | H3: =IF(H1>=Assumptions!$C$64,1,0) -> 0 | I3: =IF(I1>=Assumptions!$C$64,1,0) -> 0 | ... AK3: =IF(AK1>=Assumptions!$C$64,1,0) -> 1
A4: Growth dampener | B4: =IF(B3=1,Assumptions!$C$65,1) -> 1 | C4: =IF(C3=1,Assumptions!$C$65,1) -> 1 | D4: =IF(D3=1,Assumptions!$C$65,1) -> 1 | E4: =IF(E3=1,Assumptions!$C$65,1) -> 1 | F4: =IF(F3=1,Assumptions!$C$65,1) -> 1 | G4: =IF(G3=1,Assumptions!$C$65,1) -> 1 | H4: =IF(H3=1,Assumptions!$C$65,1) -> 1 | I4: =IF(I3=1,Assumptions!$C$65,1) -> 1 | ... AK4: =IF(AK3=1,Assumptions!$C$65,1) -> 0.8
A5: Price per team (£) | B5: =Assumptions!$C$34*IF(B3=1,Assumptions!$C$66,1) -> 45 | C5: =Assumptions!$C$34*IF(C3=1,Assumptions!$C$66,1) -> 45 | D5: =Assumptions!$C$34*IF(D3=1,Assumptions!$C$66,1) -> 45 | E5: =Assumptions!$C$34*IF(E3=1,Assumptions!$C$66,1) -> 45 | F5: =Assumptions!$C$34*IF(F3=1,Assumptions!$C$66,1) -> 45 | G5: =Assumptions!$C$34*IF(G3=1,Assumptions!$C$66,1) -> 45 | H5: =Assumptions!$C$34*IF(H3=1,Assumptions!$C$66,1) -> 45 | I5: =Assumptions!$C$34*IF(I3=1,Assumptions!$C$66,1) -> 45 | ... AK5: =Assumptions!$C$34*IF(AK3=1,Assumptions!$C$66,1) -> 40.5
A6: Marketing spend (£) | B6: =IF(B1<3,Assumptions!$C$38/3,CHOOSE(B2,Assumptions!$C$39,Assumptions!$C$40,Assumptions!$C$41)) -> 133333.33 | C6: =IF(C1<3,Assumptions!$C$38/3,CHOOSE(C2,Assumptions!$C$39,Assumptions!$C$40,Assumptions!$C$41)) -> 133333.33 | D6: =IF(D1<3,Assumptions!$C$38/3,CHOOSE(D2,Assumptions!$C$39,Assumptions!$C$40,Assumptions!$C$41)) -> 133333.33 | E6: =IF(E1<3,Assumptions!$C$38/3,CHOOSE(E2,Assumptions!$C$39,Assumptions!$C$40,Assumptions!$C$41)) -> 27000 | F6: =IF(F1<3,Assumptions!$C$38/3,CHOOSE(F2,Assumptions!$C$39,Assumptions!$C$40,Assumptions!$C$41)) -> 27000 | G6: =IF(G1<3,Assumptions!$C$38/3,CHOOSE(G2,Assumptions!$C$39,Assumptions!$C$40,Assumptions!$C$41)) -> 27000 | H6: =IF(H1<3,Assumptions!$C$38/3,CHOOSE(H2,Assumptions!$C$39,Assumptions!$C$40,Assumptions!$C$41)) -> 27000 | I6: =IF(I1<3,Assumptions!$C$38/3,CHOOSE(I2,Assumptions!$C$39,Assumptions!$C$40,Assumptions!$C$41)) -> 27000 | ... AK6: =IF(AK1<3,Assumptions!$C$38/3,CHOOSE(AK2,Assumptions!$C$39,Assumptions!$C$40,Assumptions!$C$41)) -> 15000
A7: Installs | B7: =B6/Assumptions!$C$26*CHOOSE(B2,Assumptions!$C$27,Assumptions!$C$28,Assumptions!$C$29)*B4 -> 100000 | C7: =C6/Assumptions!$C$26*CHOOSE(C2,Assumptions!$C$27,Assumptions!$C$28,Assumptions!$C$29)*C4 -> 100000 | D7: =D6/Assumptions!$C$26*CHOOSE(D2,Assumptions!$C$27,Assumptions!$C$28,Assumptions!$C$29)*D4 -> 100000 | E7: =E6/Assumptions!$C$26*CHOOSE(E2,Assumptions!$C$27,Assumptions!$C$28,Assumptions!$C$29)*E4 -> 20250 | F7: =F6/Assumptions!$C$26*CHOOSE(F2,Assumptions!$C$27,Assumptions!$C$28,Assumptions!$C$29)*F4 -> 20250 | G7: =G6/Assumptions!$C$26*CHOOSE(G2,Assumptions!$C$27,Assumptions!$C$28,Assumptions!$C$29)*G4 -> 20250 | H7: =H6/Assumptions!$C$26*CHOOSE(H2,Assumptions!$C$27,Assumptions!$C$28,Assumptions!$C$29)*H4 -> 20250 | I7: =I6/Assumptions!$C$26*CHOOSE(I2,Assumptions!$C$27,Assumptions!$C$28,Assumptions!$C$29)*I4 -> 20250 | ... AK7: =AK6/Assumptions!$C$26*CHOOSE(AK2,Assumptions!$C$27,Assumptions!$C$28,Assumptions!$C$29)*AK4 -> 7500
A8: New active players | B8: =B7*Assumptions!$C$30 -> 30000 | C8: =C7*Assumptions!$C$30 -> 30000 | D8: =D7*Assumptions!$C$30 -> 30000 | E8: =E7*Assumptions!$C$30 -> 6075 | F8: =F7*Assumptions!$C$30 -> 6075 | G8: =G7*Assumptions!$C$30 -> 6075 | H8: =H7*Assumptions!$C$30 -> 6075 | I8: =I7*Assumptions!$C$30 -> 6075 | ... AK8: =AK7*Assumptions!$C$30 -> 2250
A9: New active teams | B9: =B8/Assumptions!$B$6 -> 8571.4286 | C9: =C8/Assumptions!$B$6 -> 8571.4286 | D9: =D8/Assumptions!$B$6 -> 8571.4286 | E9: =E8/Assumptions!$B$6 -> 1735.7143 | F9: =F8/Assumptions!$B$6 -> 1735.7143 | G9: =G8/Assumptions!$B$6 -> 1735.7143 | H9: =H8/Assumptions!$B$6 -> 1735.7143 | I9: =I8/Assumptions!$B$6 -> 1735.7143 | ... AK9: =AK8/Assumptions!$B$6 -> 642.85714
A10: Backlog pool (teams) | B10: =B9 -> 8571.4286 | C10: =IF(C1<Assumptions!$B$7,B10+C9,IF(C1<=Assumptions!$B$7+1,B10*2/3,0)) -> 17142.857 | D10: =IF(D1<Assumptions!$B$7,C10+D9,IF(D1<=Assumptions!$B$7+1,C10*2/3,0)) -> 25714.286 | E10: =IF(E1<Assumptions!$B$7,D10+E9,IF(E1<=Assumptions!$B$7+1,D10*2/3,0)) -> 27450 | F10: =IF(F1<Assumptions!$B$7,E10+F9,IF(F1<=Assumptions!$B$7+1,E10*2/3,0)) -> 29185.714 | G10: =IF(G1<Assumptions!$B$7,F10+G9,IF(G1<=Assumptions!$B$7+1,F10*2/3,0)) -> 30921.429 | H10: =IF(H1<Assumptions!$B$7,G10+H9,IF(H1<=Assumptions!$B$7+1,G10*2/3,0)) -> 32657.143 | I10: =IF(I1<Assumptions!$B$7,H10+I9,IF(I1<=Assumptions!$B$7+1,H10*2/3,0)) -> 34392.857 | J10: =IF(J1<Assumptions!$B$7,I10+J9,IF(J1<=Assumptions!$B$7+1,I10*2/3,0)) -> 36128.571 | ... AK10: =IF(AK1<Assumptions!$B$7,AJ10+AK9,IF(AK1<=Assumptions!$B$7+1,AJ10*2/3,0)) -> 0
A11: Backlog tranche | B11: =0 -> 0 | C11: =IF(C1<Assumptions!$B$7,0,IF(C1<=Assumptions!$B$7+1,B10/3,IF(C1=Assumptions!$B$7+2,B10,0))) -> 0 | D11: =IF(D1<Assumptions!$B$7,0,IF(D1<=Assumptions!$B$7+1,C10/3,IF(D1=Assumptions!$B$7+2,C10,0))) -> 0 | E11: =IF(E1<Assumptions!$B$7,0,IF(E1<=Assumptions!$B$7+1,D10/3,IF(E1=Assumptions!$B$7+2,D10,0))) -> 0 | F11: =IF(F1<Assumptions!$B$7,0,IF(F1<=Assumptions!$B$7+1,E10/3,IF(F1=Assumptions!$B$7+2,E10,0))) -> 0 | G11: =IF(G1<Assumptions!$B$7,0,IF(G1<=Assumptions!$B$7+1,F10/3,IF(G1=Assumptions!$B$7+2,F10,0))) -> 0 | H11: =IF(H1<Assumptions!$B$7,0,IF(H1<=Assumptions!$B$7+1,G10/3,IF(H1=Assumptions!$B$7+2,G10,0))) -> 0 | I11: =IF(I1<Assumptions!$B$7,0,IF(I1<=Assumptions!$B$7+1,H10/3,IF(I1=Assumptions!$B$7+2,H10,0))) -> 0 | J11: =IF(J1<Assumptions!$B$7,0,IF(J1<=Assumptions!$B$7+1,I10/3,IF(J1=Assumptions!$B$7+2,I10,0))) -> 0 | ... AK11: =IF(AK1<Assumptions!$B$7,0,IF(AK1<=Assumptions!$B$7+1,AJ10/3,IF(AK1=Assumptions!$B$7+2,AJ10,0))) -> 0
A12: New paying teams | B12: =B11*Assumptions!$C$31+IF(B1>=Assumptions!$B$7,B9*Assumptions!$C$32,0) -> 0 | C12: =C11*Assumptions!$C$31+IF(C1>=Assumptions!$B$7,C9*Assumptions!$C$32,0) -> 0 | D12: =D11*Assumptions!$C$31+IF(D1>=Assumptions!$B$7,D9*Assumptions!$C$32,0) -> 0 | E12: =E11*Assumptions!$C$31+IF(E1>=Assumptions!$B$7,E9*Assumptions!$C$32,0) -> 0 | F12: =F11*Assumptions!$C$31+IF(F1>=Assumptions!$B$7,F9*Assumptions!$C$32,0) -> 0 | G12: =G11*Assumptions!$C$31+IF(G1>=Assumptions!$B$7,G9*Assumptions!$C$32,0) -> 0 | H12: =H11*Assumptions!$C$31+IF(H1>=Assumptions!$B$7,H9*Assumptions!$C$32,0) -> 0 | I12: =I11*Assumptions!$C$31+IF(I1>=Assumptions!$B$7,I9*Assumptions!$C$32,0) -> 0 | ... AK12: =AK11*Assumptions!$C$31+IF(AK1>=Assumptions!$B$7,AK9*Assumptions!$C$32,0) -> 64.285714
A13: Repeat rate (monthly) | B13: =MIN(Assumptions!$C$33,CHOOSE(B2,Assumptions!$C$58,Assumptions!$C$59,Assumptions!$C$60)/Assumptions!$B$5)/12 -> 0.083333333 | C13: =MIN(Assumptions!$C$33,CHOOSE(C2,Assumptions!$C$58,Assumptions!$C$59,Assumptions!$C$60)/Assumptions!$B$5)/12 -> 0.083333333 | D13: =MIN(Assumptions!$C$33,CHOOSE(D2,Assumptions!$C$58,Assumptions!$C$59,Assumptions!$C$60)/Assumptions!$B$5)/12 -> 0.083333333 | E13: =MIN(Assumptions!$C$33,CHOOSE(E2,Assumptions!$C$58,Assumptions!$C$59,Assumptions!$C$60)/Assumptions!$B$5)/12 -> 0.083333333 | F13: =MIN(Assumptions!$C$33,CHOOSE(F2,Assumptions!$C$58,Assumptions!$C$59,Assumptions!$C$60)/Assumptions!$B$5)/12 -> 0.083333333 | G13: =MIN(Assumptions!$C$33,CHOOSE(G2,Assumptions!$C$58,Assumptions!$C$59,Assumptions!$C$60)/Assumptions!$B$5)/12 -> 0.083333333 | H13: =MIN(Assumptions!$C$33,CHOOSE(H2,Assumptions!$C$58,Assumptions!$C$59,Assumptions!$C$60)/Assumptions!$B$5)/12 -> 0.083333333 | I13: =MIN(Assumptions!$C$33,CHOOSE(I2,Assumptions!$C$58,Assumptions!$C$59,Assumptions!$C$60)/Assumptions!$B$5)/12 -> 0.083333333 | ... AK13: =MIN(Assumptions!$C$33,CHOOSE(AK2,Assumptions!$C$58,Assumptions!$C$59,Assumptions!$C$60)/Assumptions!$B$5)/12 -> 0.066666667
A14: Repeat purchases | B14: =0 -> 0 | C14: =B15*C13 -> 0 | D14: =C15*D13 -> 0 | E14: =D15*E13 -> 0 | F14: =E15*F13 -> 0 | G14: =F15*G13 -> 0 | H14: =G15*H13 -> 0 | I14: =H15*I13 -> 0 | J14: =I15*J13 -> 0 | ... AK14: =AJ15*AK13 -> 123.21536
A15: Paying-team base | B15: =B12 -> 0 | C15: =B15*(1-Assumptions!$B$23)+C12 -> 0 | D15: =C15*(1-Assumptions!$B$23)+D12 -> 0 | E15: =D15*(1-Assumptions!$B$23)+E12 -> 0 | F15: =E15*(1-Assumptions!$B$23)+F12 -> 0 | G15: =F15*(1-Assumptions!$B$23)+G12 -> 0 | H15: =G15*(1-Assumptions!$B$23)+H12 -> 0 | I15: =H15*(1-Assumptions!$B$23)+I12 -> 0 | J15: =I15*(1-Assumptions!$B$23)+J12 -> 0 | ... AK15: =AJ15*(1-Assumptions!$B$23)+AK12 -> 1820.1046
A16: Paid team purchases | B16: =B12+B14 -> 0 | C16: =C12+C14 -> 0 | D16: =D12+D14 -> 0 | E16: =E12+E14 -> 0 | F16: =F12+F14 -> 0 | G16: =G12+G14 -> 0 | H16: =H12+H14 -> 0 | I16: =I12+I14 -> 0 | ... AK16: =AK12+AK14 -> 187.50108
A17: Direct consumer net (£) | B17: =B16*B5*(1-Assumptions!$B$19) -> 0 | C17: =C16*C5*(1-Assumptions!$B$19) -> 0 | D17: =D16*D5*(1-Assumptions!$B$19) -> 0 | E17: =E16*E5*(1-Assumptions!$B$19) -> 0 | F17: =F16*F5*(1-Assumptions!$B$19) -> 0 | G17: =G16*G5*(1-Assumptions!$B$19) -> 0 | H17: =H16*H5*(1-Assumptions!$B$19) -> 0 | I17: =I16*I5*(1-Assumptions!$B$19) -> 0 | ... AK17: =AK16*AK5*(1-Assumptions!$B$19) -> 6986.2901
A18: OTA teams | B18: =IF(B1>=Assumptions!$B$7,CHOOSE(B2,Assumptions!$C$35,Assumptions!$C$36,Assumptions!$C$37)*Assumptions!$B$5*B4,0) -> 0 | C18: =IF(C1>=Assumptions!$B$7,CHOOSE(C2,Assumptions!$C$35,Assumptions!$C$36,Assumptions!$C$37)*Assumptions!$B$5*C4,0) -> 0 | D18: =IF(D1>=Assumptions!$B$7,CHOOSE(D2,Assumptions!$C$35,Assumptions!$C$36,Assumptions!$C$37)*Assumptions!$B$5*D4,0) -> 0 | E18: =IF(E1>=Assumptions!$B$7,CHOOSE(E2,Assumptions!$C$35,Assumptions!$C$36,Assumptions!$C$37)*Assumptions!$B$5*E4,0) -> 0 | F18: =IF(F1>=Assumptions!$B$7,CHOOSE(F2,Assumptions!$C$35,Assumptions!$C$36,Assumptions!$C$37)*Assumptions!$B$5*F4,0) -> 0 | G18: =IF(G1>=Assumptions!$B$7,CHOOSE(G2,Assumptions!$C$35,Assumptions!$C$36,Assumptions!$C$37)*Assumptions!$B$5*G4,0) -> 0 | H18: =IF(H1>=Assumptions!$B$7,CHOOSE(H2,Assumptions!$C$35,Assumptions!$C$36,Assumptions!$C$37)*Assumptions!$B$5*H4,0) -> 0 | I18: =IF(I1>=Assumptions!$B$7,CHOOSE(I2,Assumptions!$C$35,Assumptions!$C$36,Assumptions!$C$37)*Assumptions!$B$5*I4,0) -> 0 | ... AK18: =IF(AK1>=Assumptions!$B$7,CHOOSE(AK2,Assumptions!$C$35,Assumptions!$C$36,Assumptions!$C$37)*Assumptions!$B$5*AK4,0) -> 160
A19: OTA net (£) | B19: =B18*B5*(1-Assumptions!$B$20) -> 0 | C19: =C18*C5*(1-Assumptions!$B$20) -> 0 | D19: =D18*D5*(1-Assumptions!$B$20) -> 0 | E19: =E18*E5*(1-Assumptions!$B$20) -> 0 | F19: =F18*F5*(1-Assumptions!$B$20) -> 0 | G19: =G18*G5*(1-Assumptions!$B$20) -> 0 | H19: =H18*H5*(1-Assumptions!$B$20) -> 0 | I19: =I18*I5*(1-Assumptions!$B$20) -> 0 | ... AK19: =AK18*AK5*(1-Assumptions!$B$20) -> 4860
A20: Cumulative players | B20: =B8+B18*Assumptions!$B$6*Assumptions!$B$9 -> 30000 | C20: =B20+C8+C18*Assumptions!$B$6*Assumptions!$B$9 -> 60000 | D20: =C20+D8+D18*Assumptions!$B$6*Assumptions!$B$9 -> 90000 | E20: =D20+E8+E18*Assumptions!$B$6*Assumptions!$B$9 -> 96075 | F20: =E20+F8+F18*Assumptions!$B$6*Assumptions!$B$9 -> 102150 | G20: =F20+G8+G18*Assumptions!$B$6*Assumptions!$B$9 -> 108225 | H20: =G20+H8+H18*Assumptions!$B$6*Assumptions!$B$9 -> 114300 | I20: =H20+I8+I18*Assumptions!$B$6*Assumptions!$B$9 -> 120375 | J20: =I20+J8+J18*Assumptions!$B$6*Assumptions!$B$9 -> 126450 | ... AK20: =AJ20+AK8+AK18*Assumptions!$B$6*Assumptions!$B$9 -> 218070
A21: MAU | B21: =B8+Assumptions!$B$8*B20 -> 32400 | C21: =C8+Assumptions!$B$8*C20 -> 34800 | D21: =D8+Assumptions!$B$8*D20 -> 37200 | E21: =E8+Assumptions!$B$8*E20 -> 13761 | F21: =F8+Assumptions!$B$8*F20 -> 14247 | G21: =G8+Assumptions!$B$8*G20 -> 14733 | H21: =H8+Assumptions!$B$8*H20 -> 15219 | I21: =I8+Assumptions!$B$8*I20 -> 15705 | ... AK21: =AK8+Assumptions!$B$8*AK20 -> 19695.6
A22: Advertising (£) | B22: =IF(B1>=Assumptions!$B$7,B21/1000*Assumptions!$C$50,0) -> 0 | C22: =IF(C1>=Assumptions!$B$7,C21/1000*Assumptions!$C$50,0) -> 0 | D22: =IF(D1>=Assumptions!$B$7,D21/1000*Assumptions!$C$50,0) -> 0 | E22: =IF(E1>=Assumptions!$B$7,E21/1000*Assumptions!$C$50,0) -> 0 | F22: =IF(F1>=Assumptions!$B$7,F21/1000*Assumptions!$C$50,0) -> 0 | G22: =IF(G1>=Assumptions!$B$7,G21/1000*Assumptions!$C$50,0) -> 0 | H22: =IF(H1>=Assumptions!$B$7,H21/1000*Assumptions!$C$50,0) -> 0 | I22: =IF(I1>=Assumptions!$B$7,I21/1000*Assumptions!$C$50,0) -> 0 | ... AK22: =IF(AK1>=Assumptions!$B$7,AK21/1000*Assumptions!$C$50,0) -> 492.39
A23: Sponsorship (£) | B23: =IF(B1>=Assumptions!$B$7,CHOOSE(B2,Assumptions!$C$43,Assumptions!$C$44,Assumptions!$C$45)*Assumptions!$C$42/12,0) -> 0 | C23: =IF(C1>=Assumptions!$B$7,CHOOSE(C2,Assumptions!$C$43,Assumptions!$C$44,Assumptions!$C$45)*Assumptions!$C$42/12,0) -> 0 | D23: =IF(D1>=Assumptions!$B$7,CHOOSE(D2,Assumptions!$C$43,Assumptions!$C$44,Assumptions!$C$45)*Assumptions!$C$42/12,0) -> 0 | E23: =IF(E1>=Assumptions!$B$7,CHOOSE(E2,Assumptions!$C$43,Assumptions!$C$44,Assumptions!$C$45)*Assumptions!$C$42/12,0) -> 0 | F23: =IF(F1>=Assumptions!$B$7,CHOOSE(F2,Assumptions!$C$43,Assumptions!$C$44,Assumptions!$C$45)*Assumptions!$C$42/12,0) -> 0 | G23: =IF(G1>=Assumptions!$B$7,CHOOSE(G2,Assumptions!$C$43,Assumptions!$C$44,Assumptions!$C$45)*Assumptions!$C$42/12,0) -> 0 | H23: =IF(H1>=Assumptions!$B$7,CHOOSE(H2,Assumptions!$C$43,Assumptions!$C$44,Assumptions!$C$45)*Assumptions!$C$42/12,0) -> 0 | I23: =IF(I1>=Assumptions!$B$7,CHOOSE(I2,Assumptions!$C$43,Assumptions!$C$44,Assumptions!$C$45)*Assumptions!$C$42/12,0) -> 0 | ... AK23: =IF(AK1>=Assumptions!$B$7,CHOOSE(AK2,Assumptions!$C$43,Assumptions!$C$44,Assumptions!$C$45)*Assumptions!$C$42/12,0) -> 10000
A24: White-label (£) | B24: =CHOOSE(B2,Assumptions!$C$46,Assumptions!$C$47,Assumptions!$C$48)*Assumptions!$C$49/12 -> 1250 | C24: =CHOOSE(C2,Assumptions!$C$46,Assumptions!$C$47,Assumptions!$C$48)*Assumptions!$C$49/12 -> 1250 | D24: =CHOOSE(D2,Assumptions!$C$46,Assumptions!$C$47,Assumptions!$C$48)*Assumptions!$C$49/12 -> 1250 | E24: =CHOOSE(E2,Assumptions!$C$46,Assumptions!$C$47,Assumptions!$C$48)*Assumptions!$C$49/12 -> 1250 | F24: =CHOOSE(F2,Assumptions!$C$46,Assumptions!$C$47,Assumptions!$C$48)*Assumptions!$C$49/12 -> 1250 | G24: =CHOOSE(G2,Assumptions!$C$46,Assumptions!$C$47,Assumptions!$C$48)*Assumptions!$C$49/12 -> 1250 | H24: =CHOOSE(H2,Assumptions!$C$46,Assumptions!$C$47,Assumptions!$C$48)*Assumptions!$C$49/12 -> 1250 | I24: =CHOOSE(I2,Assumptions!$C$46,Assumptions!$C$47,Assumptions!$C$48)*Assumptions!$C$49/12 -> 1250 | ... AK24: =CHOOSE(AK2,Assumptions!$C$46,Assumptions!$C$47,Assumptions!$C$48)*Assumptions!$C$49/12 -> 7500
A25: Corporate revenue (£) | B25: =CHOOSE(B2,Assumptions!$C$51,Assumptions!$C$52,Assumptions!$C$53)*Assumptions!$C$54 -> 2500 | C25: =CHOOSE(C2,Assumptions!$C$51,Assumptions!$C$52,Assumptions!$C$53)*Assumptions!$C$54 -> 2500 | D25: =CHOOSE(D2,Assumptions!$C$51,Assumptions!$C$52,Assumptions!$C$53)*Assumptions!$C$54 -> 2500 | E25: =CHOOSE(E2,Assumptions!$C$51,Assumptions!$C$52,Assumptions!$C$53)*Assumptions!$C$54 -> 2500 | F25: =CHOOSE(F2,Assumptions!$C$51,Assumptions!$C$52,Assumptions!$C$53)*Assumptions!$C$54 -> 2500 | G25: =CHOOSE(G2,Assumptions!$C$51,Assumptions!$C$52,Assumptions!$C$53)*Assumptions!$C$54 -> 2500 | H25: =CHOOSE(H2,Assumptions!$C$51,Assumptions!$C$52,Assumptions!$C$53)*Assumptions!$C$54 -> 2500 | I25: =CHOOSE(I2,Assumptions!$C$51,Assumptions!$C$52,Assumptions!$C$53)*Assumptions!$C$54 -> 2500 | ... AK25: =CHOOSE(AK2,Assumptions!$C$51,Assumptions!$C$52,Assumptions!$C$53)*Assumptions!$C$54 -> 20000
A26: TOTAL REVENUE (£) | B26: =B17+B19+B22+B23+B24+B25 -> 3750 | C26: =C17+C19+C22+C23+C24+C25 -> 3750 | D26: =D17+D19+D22+D23+D24+D25 -> 3750 | E26: =E17+E19+E22+E23+E24+E25 -> 3750 | F26: =F17+F19+F22+F23+F24+F25 -> 3750 | G26: =G17+G19+G22+G23+G24+G25 -> 3750 | H26: =H17+H19+H22+H23+H24+H25 -> 3750 | I26: =I17+I19+I22+I23+I24+I25 -> 3750 | ... AK26: =AK17+AK19+AK22+AK23+AK24+AK25 -> 49838.68
A27: New hunts built | B27: =CHOOSE(B2,Assumptions!$C$58,Assumptions!$C$59,Assumptions!$C$60)/12 -> 0.83333333 | C27: =CHOOSE(C2,Assumptions!$C$58,Assumptions!$C$59,Assumptions!$C$60)/12 -> 0.83333333 | D27: =CHOOSE(D2,Assumptions!$C$58,Assumptions!$C$59,Assumptions!$C$60)/12 -> 0.83333333 | E27: =CHOOSE(E2,Assumptions!$C$58,Assumptions!$C$59,Assumptions!$C$60)/12 -> 0.83333333 | F27: =CHOOSE(F2,Assumptions!$C$58,Assumptions!$C$59,Assumptions!$C$60)/12 -> 0.83333333 | G27: =CHOOSE(G2,Assumptions!$C$58,Assumptions!$C$59,Assumptions!$C$60)/12 -> 0.83333333 | H27: =CHOOSE(H2,Assumptions!$C$58,Assumptions!$C$59,Assumptions!$C$60)/12 -> 0.83333333 | I27: =CHOOSE(I2,Assumptions!$C$58,Assumptions!$C$59,Assumptions!$C$60)/12 -> 0.83333333 | ... AK27: =CHOOSE(AK2,Assumptions!$C$58,Assumptions!$C$59,Assumptions!$C$60)/12 -> 0.66666667
A28: Live hunts | B28: =Assumptions!$B$5+B27 -> 10.833333 | C28: =B28+C27 -> 11.666667 | D28: =C28+D27 -> 12.5 | E28: =D28+E27 -> 13.333333 | F28: =E28+F27 -> 14.166667 | G28: =F28+G27 -> 15 | H28: =G28+H27 -> 15.833333 | I28: =H28+I27 -> 16.666667 | J28: =I28+J27 -> 17.5 | ... AK28: =AJ28+AK27 -> 36
A29: Content build (£) | B29: =IF(B1=0,Assumptions!$B$12+Assumptions!$B$16+(Assumptions!$B$5-1)*(Assumptions!$B$13+Assumptions!$B$16),0)+B27*(Assumptions!$B$13*Assumptions!$B$11+Assumptions!$B$16) -> 149916.67 | C29: =IF(C1=0,Assumptions!$B$12+Assumptions!$B$16+(Assumptions!$B$5-1)*(Assumptions!$B$13+Assumptions!$B$16),0)+C27*(Assumptions!$B$13*Assumptions!$B$11+Assumptions!$B$16) -> 10916.667 | D29: =IF(D1=0,Assumptions!$B$12+Assumptions!$B$16+(Assumptions!$B$5-1)*(Assumptions!$B$13+Assumptions!$B$16),0)+D27*(Assumptions!$B$13*Assumptions!$B$11+Assumptions!$B$16) -> 10916.667 | E29: =IF(E1=0,Assumptions!$B$12+Assumptions!$B$16+(Assumptions!$B$5-1)*(Assumptions!$B$13+Assumptions!$B$16),0)+E27*(Assumptions!$B$13*Assumptions!$B$11+Assumptions!$B$16) -> 10916.667 | F29: =IF(F1=0,Assumptions!$B$12+Assumptions!$B$16+(Assumptions!$B$5-1)*(Assumptions!$B$13+Assumptions!$B$16),0)+F27*(Assumptions!$B$13*Assumptions!$B$11+Assumptions!$B$16) -> 10916.667 | G29: =IF(G1=0,Assumptions!$B$12+Assumptions!$B$16+(Assumptions!$B$5-1)*(Assumptions!$B$13+Assumptions!$B$16),0)+G27*(Assumptions!$B$13*Assumptions!$B$11+Assumptions!$B$16) -> 10916.667 | H29: =IF(H1=0,Assumptions!$B$12+Assumptions!$B$16+(Assumptions!$B$5-1)*(Assumptions!$B$13+Assumptions!$B$16),0)+H27*(Assumptions!$B$13*Assumptions!$B$11+Assumptions!$B$16) -> 10916.667 | I29: =IF(I1=0,Assumptions!$B$12+Assumptions!$B$16+(Assumptions!$B$5-1)*(Assumptions!$B$13+Assumptions!$B$16),0)+I27*(Assumptions!$B$13*Assumptions!$B$11+Assumptions!$B$16) -> 10916.667 | ... AK29: =IF(AK1=0,Assumptions!$B$12+Assumptions!$B$16+(Assumptions!$B$5-1)*(Assumptions!$B$13+Assumptions!$B$16),0)+AK27*(Assumptions!$B$13*Assumptions!$B$11+Assumptions!$B$16) -> 8733.3333
A30: Content maintenance (£) | B30: =B28*CHOOSE(B2,Assumptions!$C$61,Assumptions!$C$62,Assumptions!$C$63)*(Assumptions!$B$10*Assumptions!$B$14+(1-Assumptions!$B$10)*Assumptions!$B$15)/12 -> 2080.9028 | C30: =C28*CHOOSE(C2,Assumptions!$C$61,Assumptions!$C$62,Assumptions!$C$63)*(Assumptions!$B$10*Assumptions!$B$14+(1-Assumptions!$B$10)*Assumptions!$B$15)/12 -> 2240.9722 | D30: =D28*CHOOSE(D2,Assumptions!$C$61,Assumptions!$C$62,Assumptions!$C$63)*(Assumptions!$B$10*Assumptions!$B$14+(1-Assumptions!$B$10)*Assumptions!$B$15)/12 -> 2401.0417 | E30: =E28*CHOOSE(E2,Assumptions!$C$61,Assumptions!$C$62,Assumptions!$C$63)*(Assumptions!$B$10*Assumptions!$B$14+(1-Assumptions!$B$10)*Assumptions!$B$15)/12 -> 2561.1111 | F30: =F28*CHOOSE(F2,Assumptions!$C$61,Assumptions!$C$62,Assumptions!$C$63)*(Assumptions!$B$10*Assumptions!$B$14+(1-Assumptions!$B$10)*Assumptions!$B$15)/12 -> 2721.1806 | G30: =G28*CHOOSE(G2,Assumptions!$C$61,Assumptions!$C$62,Assumptions!$C$63)*(Assumptions!$B$10*Assumptions!$B$14+(1-Assumptions!$B$10)*Assumptions!$B$15)/12 -> 2881.25 | H30: =H28*CHOOSE(H2,Assumptions!$C$61,Assumptions!$C$62,Assumptions!$C$63)*(Assumptions!$B$10*Assumptions!$B$14+(1-Assumptions!$B$10)*Assumptions!$B$15)/12 -> 3041.3194 | I30: =I28*CHOOSE(I2,Assumptions!$C$61,Assumptions!$C$62,Assumptions!$C$63)*(Assumptions!$B$10*Assumptions!$B$14+(1-Assumptions!$B$10)*Assumptions!$B$15)/12 -> 3201.3889 | ... AK30: =AK28*CHOOSE(AK2,Assumptions!$C$61,Assumptions!$C$62,Assumptions!$C$63)*(Assumptions!$B$10*Assumptions!$B$14+(1-Assumptions!$B$10)*Assumptions!$B$15)/12 -> 6915
A31: Staff (£) | B31: =CHOOSE(B2,Assumptions!$C$55,Assumptions!$C$56,Assumptions!$C$57) -> 22000 | C31: =CHOOSE(C2,Assumptions!$C$55,Assumptions!$C$56,Assumptions!$C$57) -> 22000 | D31: =CHOOSE(D2,Assumptions!$C$55,Assumptions!$C$56,Assumptions!$C$57) -> 22000 | E31: =CHOOSE(E2,Assumptions!$C$55,Assumptions!$C$56,Assumptions!$C$57) -> 22000 | F31: =CHOOSE(F2,Assumptions!$C$55,Assumptions!$C$56,Assumptions!$C$57) -> 22000 | G31: =CHOOSE(G2,Assumptions!$C$55,Assumptions!$C$56,Assumptions!$C$57) -> 22000 | H31: =CHOOSE(H2,Assumptions!$C$55,Assumptions!$C$56,Assumptions!$C$57) -> 22000 | I31: =CHOOSE(I2,Assumptions!$C$55,Assumptions!$C$56,Assumptions!$C$57) -> 22000 | ... AK31: =CHOOSE(AK2,Assumptions!$C$55,Assumptions!$C$56,Assumptions!$C$57) -> 35000
A32: Other costs (£) | B32: =IF(B1=0,Assumptions!$B$18,0)+Assumptions!$B$17+B25*Assumptions!$B$21+B24*Assumptions!$B$22 -> 47237.5 | C32: =IF(C1=0,Assumptions!$B$18,0)+Assumptions!$B$17+C25*Assumptions!$B$21+C24*Assumptions!$B$22 -> 2237.5 | D32: =IF(D1=0,Assumptions!$B$18,0)+Assumptions!$B$17+D25*Assumptions!$B$21+D24*Assumptions!$B$22 -> 2237.5 | E32: =IF(E1=0,Assumptions!$B$18,0)+Assumptions!$B$17+E25*Assumptions!$B$21+E24*Assumptions!$B$22 -> 2237.5 | F32: =IF(F1=0,Assumptions!$B$18,0)+Assumptions!$B$17+F25*Assumptions!$B$21+F24*Assumptions!$B$22 -> 2237.5 | G32: =IF(G1=0,Assumptions!$B$18,0)+Assumptions!$B$17+G25*Assumptions!$B$21+G24*Assumptions!$B$22 -> 2237.5 | H32: =IF(H1=0,Assumptions!$B$18,0)+Assumptions!$B$17+H25*Assumptions!$B$21+H24*Assumptions!$B$22 -> 2237.5 | I32: =IF(I1=0,Assumptions!$B$18,0)+Assumptions!$B$17+I25*Assumptions!$B$21+I24*Assumptions!$B$22 -> 2237.5 | ... AK32: =IF(AK1=0,Assumptions!$B$18,0)+Assumptions!$B$17+AK25*Assumptions!$B$21+AK24*Assumptions!$B$22 -> 11175
A33: TOTAL COSTS (£) | B33: =B6+B29+B30+B31+B32 -> 354568.4 | C33: =C6+C29+C30+C31+C32 -> 170728.47 | D33: =D6+D29+D30+D31+D32 -> 170888.54 | E33: =E6+E29+E30+E31+E32 -> 64715.278 | F33: =F6+F29+F30+F31+F32 -> 64875.347 | G33: =G6+G29+G30+G31+G32 -> 65035.417 | H33: =H6+H29+H30+H31+H32 -> 65195.486 | I33: =I6+I29+I30+I31+I32 -> 65355.556 | ... AK33: =AK6+AK29+AK30+AK31+AK32 -> 76823.333
A34: NET (£) | B34: =B26-B33 -> -350818.4 | C34: =C26-C33 -> -166978.47 | D34: =D26-D33 -> -167138.54 | E34: =E26-E33 -> -60965.278 | F34: =F26-F33 -> -61125.347 | G34: =G26-G33 -> -61285.417 | H34: =H26-H33 -> -61445.486 | I34: =I26-I33 -> -61605.556 | ... AK34: =AK26-AK33 -> -26984.653
A35: Cumulative net (£) | B35: =B34 -> -350818.4 | C35: =B35+C34 -> -517796.88 | D35: =C35+D34 -> -684935.42 | E35: =D35+E34 -> -745900.69 | F35: =E35+F34 -> -807026.04 | G35: =F35+G34 -> -868311.46 | H35: =G35+H34 -> -929756.94 | I35: =H35+I34 -> -991362.5 | J35: =I35+J34 -> -1053128.1 | ... AK35: =AJ35+AK34 -> -1791869.7
A36: Cumulative revenue (£) | B36: =B26 -> 3750 | C36: =B36+C26 -> 7500 | D36: =C36+D26 -> 11250 | E36: =D36+E26 -> 15000 | F36: =E36+F26 -> 18750 | G36: =F36+G26 -> 22500 | H36: =G36+H26 -> 26250 | I36: =H36+I26 -> 30000 | J36: =I36+J26 -> 33750 | ... AK36: =AJ36+AK26 -> 1214682.4

Sheet High
A1: Month | B1: 0 | C1: 1 | D1: 2 | E1: 3 | F1: 4 | G1: 5 | H1: 6 | I1: 7 | J1: 8 | K1: 9 | L1: 10 | M1: 11 | N1: 12 | O1: 13 | P1: 14 | Q1: 15 | R1: 16 | S1: 17 | T1: 18 | U1: 19 | V1: 20 | W1: 21 | X1: 22 | Y1: 23 | Z1: 24 | AA1: 25 | AB1: 26 | AC1: 27 | AD1: 28 | AE1: 29 | AF1: 30 | AG1: 31 | AH1: 32 | AI1: 33 | AJ1: 34 | AK1: 35
A2: Year | B2: =1+INT(B1/12) -> 1 | C2: =1+INT(C1/12) -> 1 | D2: =1+INT(D1/12) -> 1 | E2: =1+INT(E1/12) -> 1 | F2: =1+INT(F1/12) -> 1 | G2: =1+INT(G1/12) -> 1 | H2: =1+INT(H1/12) -> 1 | I2: =1+INT(I1/12) -> 1 | ... AK2: =1+INT(AK1/12) -> 3
A3: Post-entry flag | B3: =IF(B1>=Assumptions!$D$64,1,0) -> 0 | C3: =IF(C1>=Assumptions!$D$64,1,0) -> 0 | D3: =IF(D1>=Assumptions!$D$64,1,0) -> 0 | E3: =IF(E1>=Assumptions!$D$64,1,0) -> 0 | F3: =IF(F1>=Assumptions!$D$64,1,0) -> 0 | G3: =IF(G1>=Assumptions!$D$64,1,0) -> 0 | H3: =IF(H1>=Assumptions!$D$64,1,0) -> 0 | I3: =IF(I1>=Assumptions!$D$64,1,0) -> 0 | ... AK3: =IF(AK1>=Assumptions!$D$64,1,0) -> 1
A4: Growth dampener | B4: =IF(B3=1,Assumptions!$D$65,1) -> 1 | C4: =IF(C3=1,Assumptions!$D$65,1) -> 1 | D4: =IF(D3=1,Assumptions!$D$65,1) -> 1 | E4: =IF(E3=1,Assumptions!$D$65,1) -> 1 | F4: =IF(F3=1,Assumptions!$D$65,1) -> 1 | G4: =IF(G3=1,Assumptions!$D$65,1) -> 1 | H4: =IF(H3=1,Assumptions!$D$65,1) -> 1 | I4: =IF(I3=1,Assumptions!$D$65,1) -> 1 | ... AK4: =IF(AK3=1,Assumptions!$D$65,1) -> 0.75
A5: Price per team (£) | B5: =Assumptions!$D$34*IF(B3=1,Assumptions!$D$66,1) -> 50 | C5: =Assumptions!$D$34*IF(C3=1,Assumptions!$D$66,1) -> 50 | D5: =Assumptions!$D$34*IF(D3=1,Assumptions!$D$66,1) -> 50 | E5: =Assumptions!$D$34*IF(E3=1,Assumptions!$D$66,1) -> 50 | F5: =Assumptions!$D$34*IF(F3=1,Assumptions!$D$66,1) -> 50 | G5: =Assumptions!$D$34*IF(G3=1,Assumptions!$D$66,1) -> 50 | H5: =Assumptions!$D$34*IF(H3=1,Assumptions!$D$66,1) -> 50 | I5: =Assumptions!$D$34*IF(I3=1,Assumptions!$D$66,1) -> 50 | ... AK5: =Assumptions!$D$34*IF(AK3=1,Assumptions!$D$66,1) -> 42.5
A6: Marketing spend (£) | B6: =IF(B1<3,Assumptions!$D$38/3,CHOOSE(B2,Assumptions!$D$39,Assumptions!$D$40,Assumptions!$D$41)) -> 300000 | C6: =IF(C1<3,Assumptions!$D$38/3,CHOOSE(C2,Assumptions!$D$39,Assumptions!$D$40,Assumptions!$D$41)) -> 300000 | D6: =IF(D1<3,Assumptions!$D$38/3,CHOOSE(D2,Assumptions!$D$39,Assumptions!$D$40,Assumptions!$D$41)) -> 300000 | E6: =IF(E1<3,Assumptions!$D$38/3,CHOOSE(E2,Assumptions!$D$39,Assumptions!$D$40,Assumptions!$D$41)) -> 55000 | F6: =IF(F1<3,Assumptions!$D$38/3,CHOOSE(F2,Assumptions!$D$39,Assumptions!$D$40,Assumptions!$D$41)) -> 55000 | G6: =IF(G1<3,Assumptions!$D$38/3,CHOOSE(G2,Assumptions!$D$39,Assumptions!$D$40,Assumptions!$D$41)) -> 55000 | H6: =IF(H1<3,Assumptions!$D$38/3,CHOOSE(H2,Assumptions!$D$39,Assumptions!$D$40,Assumptions!$D$41)) -> 55000 | I6: =IF(I1<3,Assumptions!$D$38/3,CHOOSE(I2,Assumptions!$D$39,Assumptions!$D$40,Assumptions!$D$41)) -> 55000 | ... AK6: =IF(AK1<3,Assumptions!$D$38/3,CHOOSE(AK2,Assumptions!$D$39,Assumptions!$D$40,Assumptions!$D$41)) -> 40000
